Workbook

Sheet 단계매핑
A1: 단계코드 | B1: 단계명 | C1: 하위유형 | D1: 데이터셋 | E1: 컬럼번호 | F1: raw data 컬럼 헤더(문항 원문) | G1: 레이아웃 코드 | H1: 전 제품군 공통
A2: S0 | B2: 메타 (보고서 미출력) | D2: 리바랩스 · 캣독런 | E2: 0 | F2: 리크루팅 | G2: — | H2: 미출력
E3: 59 | F3: (빈 열) | G3: — | H3: 미출력
D4: 케어클 · 테크핏 | E4: 0 | F4: 응답시간 | G4: — | H4: 미출력
E5: 1 | F5: 본 설문은 ‘테크핏’의 사용성 평가를 위한 것으로, 설문에 응답하기 전에 반드시 제품을 체험해 주시기 바랍니다. | G5: — | H5: 미출력
E6: 2 | F6: 정산 방식을 선택해주세요 | G6: — | H6: 미출력
E7: 3 | F7: 휴대폰 뒷번호 4자리 | G7: — | H7: 미출력
D8: 이젠오토 · 셀케어 | E8: 0 | F8: (빈 열) | G8: — | H8: 미출력
E9: 1 | F9: 응답시간 | G9: — | H9: 미출력
E10: 2 | F10: 본인의 이름과 휴대폰 번호 끝 4자리를 입력해주세요 (예시-김oo / | G10: — | H10: 미출력
E11: 7 | F11: 차량번호를 입력해주세요 | G11: — | H11: 미출력
E12: 46 | F12: 카카오톡 채널 추가한 이미지를 업로드 해주세요. | G12: — | H12: 미출력
D13: 정리습관 | E13: 0 | F13: (빈 열) | G13: — | H13: 미출력
E14: 1 | F14: 응답시간 | G14: — | H14: 미출력
E15: 2 | F15: 본 설문은 ‘정리습관’의 사용성 테스트를 위한 것으로, 설문에 응답하기 전에 반드시 서비스를 체험해 주시기 바랍니다. | G15: — | H15: 미출력
E16: 3 | F16: 서비스 체험 인증을 위해’예상 견적 확인’ 페이지를 캡쳐하여 아래에 업로드해주세요 | G16: — | H16: 미출력
E17: 4 | F17: 휴대폰 뒷번호 4자리 | G17: — | H17: 미출력
D18: 투블럭에이아이 · 키위티 | E18: 0 | F18: Response ID | G18: — | H18: 미출력
E19: 1 | F19: Time Submitted | G19: — | H19: 미출력
E20: 2 | F20: 수준 높은 글쓰기를 위한 AI 글첨삭 서비스, 키위티 | G20: — | H20: 미출력
E21: 3 | F21: 개인정보 수집 및 이용 동의서 | G21: — | H21: 미출력
E22: 4 | F22: 리워드 증정을 위해 안내드릴 연락처를 작성해주세요 | G22: — | H22: 미출력
E23: 5 | F23: 키위티 가입에 사용한 계정을 알려주세요. | G23: — | H23: 미출력
E24: 40 | F24: 다음은 키위티 사용 가격 안내표입니다. | G24: — | H24: 미출력
E25: 41 | F25: 다음은 키위티 사용 가격 안내표입니다. | G25: — | H25: 미출력
A26: S1 | B26: 인적 사항 및 특성·경험 조사 | D26: 리바랩스 · 캣독런 | E26: 1 | F26: 나이 | G26: L10|L10b|L1|L2|L9|L20 | H26: 필수 5/5
E27: 2 | F27: 성별 | G27: L10|L10b|L1|L2|L9|L20 | H27: 필수 5/5
E28: 3 | F28: 운영체제 | G28: L10|L10b|L1|L2|L9|L20 | H28: 필수 5/5
E29: 4 | F29: 하루 평균 걷는 시간 | G29: L10|L10b|L1|L2|L9|L20 | H29: 필수 5/5
E30: 5 | F30: 일주일 기준 산책 빈도 | G30: L10|L10b|L1|L2|L9|L20 | H30: 필수 5/5
D31: 케어클 · 테크핏 | E31: 4 | F31: 나이를 입력해주세요 | G31: L10|L10b|L1|L2|L9|L20 | H31: 필수 5/5
E32: 5 | F32: 성별을 선택해주세요 | G32: L10|L10b|L1|L2|L9|L20 | H32: 필수 5/5
E33: 6 | F33: 피부 타입 | G33: L10|L10b|L1|L2|L9|L20 | H33: 필수 5/5
E34: 7 | F34: 케어클의 ‘테크핏’을 체험하기 전, 다른 홈케어 뷰티 디바이스를 사용하고 계셨나요? | G34: L10|L10b|L1|L2|L9|L20 | H34: 필수 5/5
E35: 8 | F35: 피부과에서 레이저/고주파 시술을 받은 경험이 있으신가요? | G35: L10|L10b|L1|L2|L9|L20 | H35: 필수 5/5
D36: 이젠오토 · 셀케어 | E36: 3 | F36: 나이를 입력해주세요 | G36: L10|L10b|L1|L2|L9|L20 | H36: 필수 5/5
E37: 4 | F37: 성별을 선택해주세요 | G37: L10|L10b|L1|L2|L9|L20 | H37: 필수 5/5
E38: 5 | F38: 운전 경력을 선택해주세요 | G38: L10|L10b|L1|L2|L9|L20 | H38: 필수 5/5
E39: 6 | F39: 현재 소유하고 있는 차종을 적어주세요 | G39: L10|L10b|L1|L2|L9|L20 | H39: 필수 5/5
E40: 8 | F40: 연 주행거리(km)가 얼마나 되시나요? | G40: L10|L10b|L1|L2|L9|L20 | H40: 필수 5/5
...

Sheet 레이아웃
A1: 레이아웃 코드 | B1: 레이아웃 이름 | C1: 분류 | D1: 예시 이미지 | E1: 형태 설명 | F1: 사용 단계 | G1: 생성 조건 · 판단 근거 | H1: 매핑 사용 행 수 | I1: 단계매핑에서 보기
A2: L1 | B2: 세로 막대그래프 | C2: 차트 | E2: 막대 안에 값 라벨, y축 그리드, 상단에 라벤더색 [ 응답 결과 ] 배너 | F2: S1 인적사항 / S3 타사경험 / S4 고객여정 / S5 핵심구매요소 / S8 종합·NPS | G2: · 범주형 응답의 분포를 보여줄 때 항상 만든다 · 조건 없음 : 인적사항 문항이 하나라도 있으면 문항마다 1개씩 · 단위는 '명' 또는 '%' 중 원본 보고서를 따른다 | H2: =SUMPRODUCT(--ISNUMBER(SEARCH("|"&A2&"|","|"&단계매핑!$G$2:$G$284&"|"))) -> 89 | I2: → 26행 보기
A3: L1a | B3: 세로 막대 + 평균선 | C3: 차트 | E3: L1에 전체 평균 빨간 가로선을 겹치고, 막대색·평균선색 범례를 붙임 | F3: S2 기능별 / S5 핵심구매요소 / S6 4대가치 / S9 기업요청질문 | G3: · 척도 문항이 3개 이상 반복될 때 만든다 · 평균선을 넣는 이유: 어느 항목이 평균 이하인지 한눈에 보여야 개선 대상이 잡힌다 · 항목은 만족도 내림차순 정렬. 단 태스크 플로우는 플로우 순서를 유지한다 · y축은 0부터가 아니라 정수 경계로 확대한다 (예: 4~8점) | H3: =SUMPRODUCT(--ISNUMBER(SEARCH("|"&A3&"|","|"&단계매핑!$G$2:$G$284&"|"))) -> 133 | I3: → 53행 보기
A4: L1b | B4: 만족도 분포 꺾은선 | C4: 차트 | E4: x축 0~10점, y축 응답자 수. 각 점에 값 라벨 | F4: S2 기능별 | G4: · L1(히스토그램)과 둘 중 하나만 쓴다 · 리바랩스는 히스토그램(위쪽 이미지), 이젠오토는 꺾은선(아래쪽 이미지)을 썼다 · 어느 쪽이든 제목은 '만족도 분포도'로 같다 · 담당자가 보고서 스타일을 정하면 그 하나의 그래프로 통일 | H4: =SUMPRODUCT(--ISNUMBER(SEARCH("|"&A4&"|","|"&단계매핑!$G$2:$G$284&"|"))) -> 62 | I4: → 53행 보기
A5: L2 | B5: 가로 누적 막대 (교차표) | C5: 차트 | E5: 행별로 세그먼트를 누적, 상단에 범례. 단위는 명 | F5: S1 인적사항 | G5: · 성별과 나이가 둘 다 있고, 성별이 2종 이상일 때만 만든다 · 성별이 1종이면(여성 100%) 교차 자체가 의미 없어 드롭한다 - 케어클·정리습관이 여기 해당 · 비율(%)이 아니라 실제 응답자 수를 쓴다. 표본이 적으면 %가 과장되기 때문 | H5: =SUMPRODUCT(--ISNUMBER(SEARCH("|"&A5&"|","|"&단계매핑!$G$2:$G$284&"|"))) -> 27 | I5: → 26행 보기
A6: L3 | B6: 그룹 막대그래프 | C6: 차트 | E6: 항목별로 시리즈를 나란히, 범례 + 확대 y축 | F6: 교차분석 (별도 장) | G6: · 인적 범주형이 2개 이상 있고, 각 그룹의 응답자가 5명 이상일 때만 만든다 · 5명 미만 그룹의 평균은 한두 명에 좌우돼 해석이 위험하다 · 조건 미달이면 교차분석 장을 통째로 드롭한다 · 항목 순서는 기능별 만족도 차트와 동일하게 맞춘다 (비교가 목적이므로) | H6: =SUMPRODUCT(--ISNUMBER(SEARCH("|"&A6&"|","|"&단계매핑!$G$2:$G$284&"|"))) -> 0 | I6: 매핑에 사용 안 됨
A7: L4 | B7: 레이더 차트 | C7: 차트 | E7: 방사형. 링마다 수치 라벨. [전체]/[실용성]/[즐거움] 3개를 나란히 | F7: S7 사용자 경험 품질 평가 | G7: · 같은 축의 척도 문항이 3개 이상일 때만 만든다 · 3개 미만이면 방사형이 삼각형도 안 되므로 L1a 막대로 대체 · 축 범위는 0~10 전체가 아니라 실측 최소·최대로 확대한다 - 값이 6~8에 몰려 있으면 0~10으로 그렸을 때 차이가 안 보임 · 축 라벨은 raw data 헤더에서 뽑는다 ('실용성1)' 접두를 떼고 뒷부분) | H7: =SUMPRODUCT(--ISNUMBER(SEARCH("|"&A7&"|","|"&단계매핑!$G$2:$G$284&"|"))) -> 16 | I7: → 237행 보기
A8: L4a | B8: 레이더 오버레이 | C8: 차트 | E8: L4에 여러 시리즈를 겹쳐 그리고 범례를 붙임 | F8: 교차분석 (별도 장) | G8: · L4가 만들어졌고, 성별 등으로 나눠 볼 그룹이 2개 이상일 때 · L3과 같은 그룹 크기 조건(각 5명 이상)을 따른다 · 겹치는 폴리곤이 4개를 넘으면 읽기 어려워 L3 막대로 대체 | H8: =SUMPRODUCT(--ISNUMBER(SEARCH("|"&A8&"|","|"&단계매핑!$G$2:$G$284&"|"))) -> 0 | I8: 매핑에 사용 안 됨
A9: L5 | B9: 순위 구성 누적막대 | C9: 차트 | E9: 1위~N위를 가로 누적(%)으로. 상단에 항목 범례 8색 | F9: S2 기능별 / S5 핵심구매요소 | G9: · 순위 문항이 있을 때만 만든다 · 순위 대상이 기능명이면 기능별 장에, 구매요소명이면 핵심구매요소 장에 넣는다 · 평균 순위만으로는 '1위 몰표'와 '고른 분포'를 구분할 수 없어 구성비를 함께 본다 · 순위 문항이 없으면 드롭 (이젠오토·정리습관) | H9: =SUMPRODUCT(--ISNUMBER(SEARCH("|"&A9&"|","|"&단계매핑!$G$2:$G$284&"|"))) -> 26 | I9: → 115행 보기
A10: L6 | B10: 사분면 산점도 | C10: 차트 | E10: X=상대중요도(-5~5), Y=만족도(0~10). 9칸 배경을 5단계 색으로 | F10: S2 기능별 / S5 핵심구매요소 / 결과·제언 | G10: · 순위 항목명과 만족도 항목명의 교집합이 3개 이상일 때만 만든다 · 두 축이 다 있어야 '중요한데 만족도가 낮은' 개선 우선순위가 나온다 · 제품군이 아니라 항목 교집합으로 판정한다 - 리바랩스 6개 성립 / 케어클 0개 불가 / 투블럭 6개 성립 · 한 보고서에 2번 나올 수 있다 (기능 축 + 구매요소 축) · 조건 미달이면 만족도 막대와 중요도 막대를 나란히 놓는 것으로 대체 | H10: =SUMPRODUCT(--ISNUMBER(SEARCH("|"&A10&"|","|"&단계매핑!$G$2:$G$284&"|"))) -> 32 | I10: → 115행 보기
A11: L6a | B11: 영역별 참고 지표 | C11: 차트 | E11: 좌: 9칸 우선순위 기준 이미지 / 우: 우선순위 표 + 판정기준 5줄 | F11: S2 기능별 / S5 핵심구매요소 / 결과·제언 | G11: · L6을 만들면 항상 같이 만든다. 단독으로 쓰지 않는다 · 사분면 색이 무엇을 뜻하는지 없으면 독자가 해석할 수 없기 때문 · 좌우 배치. 이미지 폭을 고정(200pt)해야 옆 표가 안 밀린다 | H11: =SUMPRODUCT(--ISNUMBER(SEARCH("|"&A11&"|","|"&단계매핑!$G$2:$G$284&"|"))) -> 32 | I11: → 115행 보기
A12: L7 | B12: NPS 척도 게이지 | C12: 차트 | E12: 0~10 사람 아이콘 11개 + 3구간 색상 + NPS 공식 박스 | F12: S8 종합 만족도 및 NPS 지수 | G12: · 항상 만든다. 조건 없음 · 데이터에 따라 달라지지 않는 고정 이미지 (Bain 척도 설명) · 코드로 그리지 않고 원본 이미지를 그대로 삽입한다 | H12: =SUMPRODUCT(--ISNUMBER(SEARCH("|"&A12&"|","|"&단계매핑!$G$2:$G$284&"|"))) -> 11 | I12: → 262행 보기
A13: L8 | B13: 극성 3분할 게이지 | C13: 차트 | E13: 반원 도넛. 긍정/부정/중립 3분할 + % 라벨 + 우측 범례 | F13: S2 기능별 / S3 타사경험 / S6 4대가치 / S9 기업요청질문 | G13: · 이유 컬럼이 있고 정성 분석이 성공했을 때 만든다 · 이유 컬럼이 없으면 극성을 판정할 원문이 없어 드롭 - 투블럭 4대 가치가 여기 해당 (수치만 출력) · 중립을 쓰지 않는 보고서는 L8a로 교체한다 | H13: =SUMPRODUCT(--ISNUMBER(SEARCH("|"&A13&"|","|"&단계매핑!$G$2:$G$284&"|"))) -> 146 | I13: → 53행 보기
... A22: L9b | B22: 설문 항목 표 | C22: 표 | E22: 좌: 단계(병합 셀) / 우: Q번호 + 문항. 하단에 총 N 문항 | F22: Ⅰ 개요 | G22: · 항상 만든다. 이 프로젝트 단계 분류의 결과가 그대로 출력되는 곳 · 문항 텍스트는 반드시 raw data 헤더에서 가져온다 - 과거 보고서를 베끼면 다른 raw data에서 틀린 표가 나온다 · 단계가 많은 문항을 가지면 행 단위로 페이지를 넘긴다 - 단계 전체를 한 덩어리로 묶으면 앞 페이지에 빈 공간이 생긴다 | H22: =SUMPRODUCT(--ISNUMBER(SEARCH("|"&A22&"|","|"&단계매핑!$G$2:$G$284&"|"))) -> 0 | I22: 매핑에 사용 안 됨
A23: L14 | B23: 경쟁재 비교표 | C23: 표 | D23: = | E23: 브랜드/제품 × 장점 × 단점 3열 | F23: S3 타사 서비스 경험 조사 | G23: · 장점과 단점을 별도 컬럼으로 받았을 때만 만든다 · 하나로만 받았으면 표가 반쪽이 돼 정성 서술로 대체 - 이젠오토·정리습관 예시만 분리 수집 · 유효 응답자 수를 표 옆에 반드시 명시한다 (게이팅 뒤라 급감함) | H23: =SUMPRODUCT(--ISNUMBER(SEARCH("|"&A23&"|","|"&단계매핑!$G$2:$G$284&"|"))) -> 19 | I23: → 149행 보기
A24: L18 | B24: 전략 과제 도출 표 | C24: 표 | E24: As Is(영역·전략방향) → To Be(전략과제·세부수행방안) 4열 | F24: 결과 종합 및 제언 | G24: · 기능 단위가 아니라 전략 영역 단위로 제언할 때 쓴다 · L9a(기능별 As-is→To-be)와 택1. 둘 다 넣지 않는다 · 기본값은 L9a. 클라이언트가 전략 관점을 요청하면 L18 · 현재는 투블럭만 해당 (좌측 이미지) · 케어클, 리바랩스는 기능별 As-is -> To-Be 양식 사용 : 결정 필요 (우측 이미지) | H24: =SUMPRODUCT(--ISNUMBER(SEARCH("|"&A24&"|","|"&단계매핑!$G$2:$G$284&"|"))) -> 0 | I24: 매핑에 사용 안 됨
A25: L20 | B25: 경험 수준 정의표 | C25: 표 | E25: 좌: 단계명(1~6단계) / 우: 설명문. 좌측 병합 라벨 | F25: S1 인적사항 및 특성·경험 조사 | G25: · 척도 선택지 자체에 설명이 필요할 때만 만든다 - '2단계 - 단순 소모품 교환'처럼 이름만으로 뜻이 안 통하는 경우 · 선택지가 자명하면(나이·성별) 만들지 않는다 · 막대그래프 바로 아래에 붙인다 · 현재는 이젠오토만 해당 (셀프 정비 경험 1~6단계) | H25: =SUMPRODUCT(--ISNUMBER(SEARCH("|"&A25&"|","|"&단계매핑!$G$2:$G$284&"|"))) -> 27 | I25: → 26행 보기
A26: L21 | B26: 기능별 고객 제언 종합 | C26: 표 | E26: 기능마다 고객 제언 1~N을 2열 표로 반복 | F26: 결과 종합 및 제언 | G26: · 기능별로 사용자 제언을 정리해 달라는 요청이 있을 때 · L18과 다르다 : 이건 사용자 원문 요약, L18은 회사 관점 전략 · 정성 분석 결과를 재사용하므로 추가 분석이 필요 없다 · 제언이 기능당 2건 미만이면 표 대신 불릿으로 낸다 | H26: =SUMPRODUCT(--ISNUMBER(SEARCH("|"&A26&"|","|"&단계매핑!$G$2:$G$284&"|"))) -> 0 | I26: 매핑에 사용 안 됨
A27: L22 | B27: NPS 요약표 | C27: 표 | E27: 평균 / NPS 지수 / 추천·중립·비추천 % | F27: S8 종합 만족도 및 NPS 지수 | G27: · 항상 만든다. 드롭 조건 없음 · 개수가 달라진다 - 추천 의향 1문항이면 표 1개 - 사용(구매) 의향 + 추천 의향 2문항이면 표 2개 · 이젠오토 실측 예시: 구매 NPS -8 / 추천 NPS 0 — 값이 달라 합칠 수 없다 · NPS 문항은 헤더에 'NPS'가 없을 수 있다. '추천할 의향'도 같이 찾는다 | H27: =SUMPRODUCT(--ISNUMBER(SEARCH("|"&A27&"|","|"&단계매핑!$G$2:$G$284&"|"))) -> 11 | I27: → 262행 보기
A28: L23 | B28: 결과 요약 항목별 표 | C28: 표 | E28: 좌: 항목명 / 우: [대괄호 소제목] + 불릿 | F28: 결과 종합 및 제언 | G28: · 항상 만든다 · 앞 장들의 결론만 모으는 자리라 새 분석이 필요 없다 · 항목은 실제로 생성된 섹션만 넣는다 (드롭된 장은 빼기) | H28: =SUMPRODUCT(--ISNUMBER(SEARCH("|"&A28&"|","|"&단계매핑!$G$2:$G$284&"|"))) -> 0 | I28: 매핑에 사용 안 됨
A29: L8t | B29: 극성 건수 표 | C29: 표 | E29: 긍정/부정/중립 각각의 비율(%)과 건수를 한 줄로. 헤더 셀에 극성별 색상 | F29: S2 기능별 / S3 타사경험 / S6 4대가치 / S9 기업요청질문 | G29: · L8(반원 도넛) 바로 아래에 항상 붙는다. 단독으로 쓰지 않는다 · 도넛은 비율만 보여줘 실제 몇 건인지 알 수 없기 때문 · 표본이 작을 때 비율만 보면 과장돼 보이는 문제도 같이 막는다 · 극성 2분할(L8a)이면 열도 2개로 줄인다 | H29: =SUMPRODUCT(--ISNUMBER(SEARCH("|"&A29&"|","|"&단계매핑!$G$2:$G$284&"|"))) -> 0 | I29: → 53행 보기
A30: L10 | B30: 장 헤더 | C30: 헤더 | E30: 남색 풀폭 배너. 예) Ⅲ. 기능별 고객 경험 평가 | F30: 전 섹션 | G30: · 장마다 반드시 1개 -> 예외 경우 존재 : 정성 분석 또는 표 양식으로 인해 장을 넘어갈 경우 or 새로운 섹션이 아직 시작하지 않은 경우는 반드시 또 넣지 않아도 된다 · 제목 문자열이 목차(L9b)와 정확히 같아야 한다 - 따로 관리하면 한쪽만 고쳤을 때 어긋난다 · 로마 숫자는 유니코드(Ⅲ) 대신 ASCII(III)를 쓴다 (폰트에 없음) | H30: =SUMPRODUCT(--ISNUMBER(SEARCH("|"&A30&"|","|"&단계매핑!$G$2:$G$284&"|"))) -> 187 | I30: → 26행 보기
A31: L10a | B31: 절 헤더 | C31: 헤더 | E31: 테두리 박스. 예) 1 │ 기능별 고객 경험 조사 결과 | F31: 전 섹션 | G31: · 한 장 안에서 조사 결과와 분석을 나눌 때 쓴다 · 절이 1개뿐이면 생략 가능 | H31: =SUMPRODUCT(--ISNUMBER(SEARCH("|"&A31&"|","|"&단계매핑!$G$2:$G$284&"|"))) -> 166 | I31: → 53행 보기
A32: L10b | B32: 문항 헤더 | C32: 헤더 | E32: 예) Q9. ‘펫과의 산책’ 기능에 대해… | F32: 전 섹션 | G32: · 문항 단위로 결과를 보여줄 때마다 · 번호는 설문 항목 표(L9b)의 Q번호와 일치시킨다 | H32: =SUMPRODUCT(--ISNUMBER(SEARCH("|"&A32&"|","|"&단계매핑!$G$2:$G$284&"|"))) -> 173 | I32: → 26행 보기
A33: L11 | B33: 정성 서술 블록 | C33: 텍스트 | E33: 극성 배너 → [카테고리] → "인용문" → ▶ 인사이트 | F33: 전 섹션 | G33: · 이유 컬럼이 있고 정성 분석이 성공했을 때 · 인용문은 반드시 원문 그대로 (요약 금지) · 인사이트 화살표는 유니코드 대신 도형으로 그린다 (폰트에 없음) · 정성 분석이 실패하면 이 블록만 빠지고 수치는 그대로 나간다 | H33: =SUMPRODUCT(--ISNUMBER(SEARCH("|"&A33&"|","|"&단계매핑!$G$2:$G$284&"|"))) -> 194 | I33: → 53행 보기
A34: L11a | B34: 극성 총평 박스 | C34: 텍스트 | E34: [긍정 의견 요약] 회색 박스 | F34: S2 기능별 | G34: · 극성 3분할(L8)일 때만. 2분할(L8a)이면 만들지 않는다 · 기본 파이프라인에서 분리된 선택 기능이다 - 문항당 최대 3회 추가 호출이 들어가 시간·비용이 는다 · 담당자가 명시적으로 요청할 때만 생성 | H34: =SUMPRODUCT(--ISNUMBER(SEARCH("|"&A34&"|","|"&단계매핑!$G$2:$G$284&"|"))) -> 62 | I34: → 53행 보기
A35: L11b | B35: 개선 아이디어 2단 | C35: 텍스트 | E35: [대분류] → <소분류> → 인용 다수. 극성·인사이트 없음 | F35: S9 개선 아이디어 | G35: · 항상 만든다 · 개선 아이디어는 좋다·나쁘다를 나눌 대상이 아니라 극성을 매기지 않는다 · 개선 문항이 2개로 분리돼 있으면 합치지 말고 각각 소절로 낸다 | H35: =SUMPRODUCT(--ISNUMBER(SEARCH("|"&A35&"|","|"&단계매핑!$G$2:$G$284&"|"))) -> 6 | I35: → 273행 보기
... A37: L24 | B37: 우선순위 종합 해석 | C37: 텍스트 | E37: 배너 제목 -> [종합 해석] 불릿 + 인사이트 -> 우선/차우선/비우선 3단계 그룹 | F37: S2 기능별 / S5 핵심구매요소 | G37: · 분석 절(3장 2절, 5장 3절)의 본문. 표가 아니라 전문 텍스트다 · 배너 제목이 순위 문항 유무로 갈린다 - 있으면 '기능별 중요 순위 및 만족도 종합 해석' - 없으면 '기능별 만족도 종합 해석' · 3단계 그룹(우선 개선/차우선 개발/비우선 개발)은 사분면 우선순위를 그대로 쓴다 - 순위 문항이 없으면 만족도 하위/상위 2단계로 낸다. 절 자체는 유지한다 · 항목마다 (상대 중요도 +2.96, 만족도 6.35)를 괄호로 병기한다 - 순위가 없으면 만족도만 병기 · 항목 아래 해석 1줄 + 니즈 1~2줄을 화살표로 잇는다 · 삼각형/화살표 기호는 폰트에 없어 도형으로 그린다 | H37: =SUMPRODUCT(--ISNUMBER(SEARCH("|"&A37&"|","|"&단계매핑!$G$2:$G$284&"|"))) -> 0 | I37: 매핑에 사용 안 됨

Sheet 표준목차
A1: 장 | B1: 장 제목 | C1: 절 | D1: 절 제목 | E1: 포함 구분 | F1: 삽입 위치 | G1: 단계코드 | H1: 판정 신호 (raw data에 이런 문항이 있으면) | I1: 판정 조건 | J1: 미충족 시 처리 | K1: 레이아웃 코드 | L1: 제품군 실적
A2: I | B2: 개요 | C2: 1 | D2: 제품 소개 | E2: 필수 | F2: 문서 시작 | G2: — | H2: 회사명 · 제품명 · 주요 기능 (raw data 아님) | I2: 담당자 입력 또는 기업소개 파일 추출 | J2: 입력 요청 후 대기 | K2: L10|L9b | L2: 5/5
A3: I | B3: 개요 | C3: 2 | D3: 사용성 테스트 진행 일정 | E3: 필수 | F3: 문서 시작 | G3: — | H3: 테스트 기간 · 대상 · 담당자 (raw data 아님) | I3: 담당자 입력 | J3: 입력 요청 후 대기 | K3: L10 | L3: 5/5
A4: I | B4: 개요 | C4: 3 | D4: 사용성 테스트 설문 항목 | E4: 필수 | F4: 문서 시작 | G4: — | H4: raw data 헤더 전체 | I4: 항상 생성. 헤더에서 결정론적으로 구성한다 | J4: — | K4: L9b | L4: 5/5
A5: II | B5: 인적 사항 및 특성·경험 조사 | C5: 1 | D5: 인적 사항 조사 결과 | E5: 필수 | F5: 개요 뒤 | G5: S1 | H5: 나이 / 성별 / 직업 / 거주 형태 / 이용 빈도 / 경험 수준 | I5: 인적 문항이 1개 이상. 장 제목은 데이터에 따라 갈린다 — · 경험 문항(2절 타사 경험 또는 경험 수준 척도)이 있으면 '인적 사항 및 특성·경험 조사' · 없으면 '인적 사항 및 특성 조사' | J5: 장 드롭 | K5: L10|L10b|L1|L2|L9|L20 | L5: raw 5/5 · 출력 4/5 (투블럭 생략)
A6: II | B6: 인적 사항 및 특성·경험 조사 | C6: 2 | D6: 타사 서비스 경험 조사 | E6: 조건부 | F6: 개요 뒤 | G6: S3 | H6: ○○ 외에 다른 서비스를 사용해 본 경험이 있으십니까? / 이용해본 서비스명 / 경험하신 서비스의 장점 · 단점 / 타사 만족도 | I6: 타사 관련 문항이 1개 이상. 원본 4종이 서로 달라 규칙으로 못 뽑는다 — 여기로 고정한다 · 케어클 Ⅱ 인적사항 p7~8 / 이젠오토 Ⅱ 인적사항 p8 · 정리습관만 Ⅲ-2 별도 절 / 리바랩스는 raw에 있으나 미출력 | J6: 절 드롭 | K6: L10b|L1|L9|L14|L8|L11 | L6: raw 4/5 · 출력 3/5 (리바랩스 미출력)
A7: III | B7: 기능별 고객 경험 평가 | C7: 1 | D7: 기능별 고객 경험 조사 결과 | E7: 필수 | F7: 인적 사항 뒤 | G7: S2 | H7: '○○' 기능의 만족도는 몇 점입니까? + 위와 같이 평가한 이유는 무엇입니까? | I7: 기능 만족도 척도 문항이 1개 이상. 기능마다 아래 블록을 그대로 반복한다 (기능 수 = 블록 수). 전부 필수다 ① 요약: 평균·표준편차(L9) → 만족도 분포도(L1b) → 주요 키워드(L12) → 감정 분석 도넛(L8) + 극성 건수 표(L8t) → 응답 요약 3박스(L11a) ② 상세: 극성별 정성 서술(L11). 카테고리 소제목 + 인용문 + 인사이트 ③ 절 마무리 — 원본 p27~28. 뒤 4개는 순위 대상이 기능일 때만 붙는다 기능별 만족도 조사 결과 그래프(L1a) + 기능별 만족도 순위 종합표(L9a) 기능 중요 순위 구성 누적막대(L5) + 기능별 중요 순위 종합표(L9a) 기능별 상대 중요도-만족도 그래프(L6) + 영역별 참고 지표(L6a) 순위 계열 4종은 기능 목록에 중요 순위가 있을 때만 붙는다 문구로 어느 목록인지 가른다. 응답 형식(단일선택/순위)은 보지 않는다 — · 기능 중 중요하다고 생각되는 순위를 1위부터 N위까지 → 기능 목록. 여기 (리바랩스 Q12, 투블럭 Q7) · 가장 영향을 미칠 수 있는 핵심 요인은 무엇이라고 → 구매요소 목록. 5장으로 (케어클 Q25 는 1~8위 순위 응답이지만 문구가 핵심 요인이라 5장이다) L6·L6a 는 같은 목록에 만족도까지 있어야 그린다 항목명 대조는 어절 포함관계로 한다 — 만족도 헤더의 짧은 이름과 순위 응답의 긴 이름이 다를 수 있다 (실시간 거점형 vs 실시간 위치 기반 거점형 콘텐츠) 항목 수 N 은 데이터가 정한다. 6개로 고정하지 않는다 극성은 긍정·부정·중립 3분할로 고정한다 (2분할 L8a 는 쓰지 않는다) 이유 문항이 기능당 2개 이상이면 합쳐서 한 입력으로 쓴다 (투블럭) L12 워드클라우드는 응답자 수와 무관하게 항상 만든다 (케어클 27명 실증) 항목이 기능이 아니라 태스크 플로우면(정리습관) 만족도 내림차순이 아니라 플로우 순서를 유지하고 표 제목을 '단계별'로 바꾼다 레이아웃은 어떤 raw data 든 동일하다. 빠지는 경우는 둘로 나뉜다 — · 원천 부재(raw 에 이유 문항이 없음): L12·L8·L8t·L11a·L11 이 빠지고 수치만 남는다. 단 5종 전부 기능마다 이유 문항이 있어 실제로는 안 일어난다 · 생성 실패(이유 문항은 있는데 LLM 호출 실패): 자리를 유지하고 '생성 실패' 로 표시한다. 절대 드롭하지 않는다 — 보고서 모양이 그날 사정에 따라 달라지면 안 되기 때문 | J7: 장 드롭 (척도 문항 자체가 없을 때만) | K7: L10|L10a|L10b|L9|L1b|L12|L8|L8t|L11a|L11|L1a|L9a|L5|L6|L6a | L7: 5/5
A8: III | B8: 기능별 고객 경험 평가 | C8: 2 | D8: 기능별 고객 경험 분석 | E8: 필수 | F8: 인적 사항 뒤 | G8: S2 | H8: 1절에서 나온 결과를 재료로 쓴다 (새 문항 아님) | I8: 기능 간 비교 해석 1페이지. 개별 기능 서술이 아니다. 전문 텍스트 (표 아님) 구성 — ① 배너 제목 순위 있음: '기능별 중요 순위 및 만족도 종합 해석' 순위 없음: '기능별 만족도 종합 해석' ② [종합 해석] 불릿 + 화살표 인사이트 · 만족도 최고 · 최저 기능 · 중요도 대비 만족도가 부족한 기능 (순위 있을 때만) · 정성에서 반복 등장한 공통 불만 ③ 우선순위 그룹 — 사분면 판정을 그대로 가져온다 순위 있음: 우선 개선 기능 / 차우선 개발 기능 / 비우선 개발 기능 3단계 순위 없음: 개선 우선 기능 / 유지 기능 2단계 (만족도 상·하위로 가른다) 항목마다 (상대 중요도 +2.96, 만족도 6.35) 병기. 순위 없으면 만족도만 항목 아래 해석 1줄 + 니즈 1~2줄 순위 문항이 없어도 절은 유지한다 — 순위 기반 요소만 빠지고 만족도 기반으로 대체해서 낸다 (이젠오토 · 정리습관) 사분면 그래프 자체는 5장 2절에서 그리고 여기서는 참조만 한다 | J8: 절 드롭 (1절 수치만 출력) | K8: L10a|L24 | L8: 5/5
A9: IV | B9: 고객 여정 기반 경험 평가 | C9: 1 | D9: 고객 여정 기반 경험 평가 조사 결과 | E9: 조건부 | F9: 기능별 고객 경험 평가 뒤 · 핵심구매요소 앞 | G9: S4 | H9: 처음 받아보셨을 때 / 1주 후 / 2주 후 같은 시점 표현 | I9: 시점 문항이 3개 이상. 컬럼 순서가 곧 시간 순서다 | J9: 장 드롭 | K9: L10|L10a|L1|L13|L9 | L9: 1/5 (케어클만)
A10: IV | B10: 고객 여정 기반 경험 평가 | C10: 2 | D10: 고객 여정 기반 경험 평가 결과 분석 | E10: 조건부 | F10: 기능별 고객 경험 평가 뒤 · 핵심구매요소 앞 | G10: S4 | H10: 시점별 이유 문항 | I10: 1절이 생성됐고 이유 문항이 있음 | J10: 절 드롭 | K10: L10a|L11 | L10: 1/5 (케어클만)
A11: V | B11: 핵심구매요소 | C11: 1 | D11: 핵심구매요소 조사 결과 | E11: 필수 | F11: 기능별(또는 고객 여정) 뒤 | G11: S5 | H11: 가장 영향을 미칠 수 있는 핵심 요인은 무엇이라고 생각하십니까? / 핵심구매요소별 만족도는 몇 점입니까? | I11: 핵심 요인 문항이 1개 이상이면 장을 만든다 ① 항상 (5/5) — 응답 형식이 달라도 1위 응답 비율 하나로 통일 단일선택형(리바랩스·이젠오토·정리습관): 그 선택이 곧 1위 순위형(케어클·투블럭): 1위 컬럼만 집계. 분모는 유효 응답 수(빈칸 제외) · 1위 응답 비율 세로 막대(L1) · No / 핵심 기능 / 순위 / 비율 4열 표(L9) 실측 대조(케어클): 우리 59.3/18.5/11.1/7.4/3.7 vs 원본 p36 60/16/12/8 ② 구매요소 목록에 중요 순위가 있을 때 (2/5 — 케어클·투블럭) · 순위 구성 누적막대(L5) + 핵심구매요소별 중요 순위 종합표(L9a) ③ 구매요소별 만족도 문항까지 있을 때 (1/5 — 투블럭 Q9~Q14) · 핵심구매요소별 평균 만족도 막대·표(L1a·L9a) · 핵심구매요소별 상대 중요도-만족도 그래프(L6) + 영역별 참고 지표(L6a) 투블럭 원본이 이 구조 그대로다 — 3장 기능 목록과 대상만 다르고 형태는 같다 리바랩스 원본 p30 에 ②③ 이 없는 것은 양식이 금지해서가 아니라 그 데이터를 묻지 않았기 때문이다. 조건이 성립하면 그린다 (2026-08-19 담당자 확정) | J11: 장 드롭 (핵심 요인 문항 자체가 없을 때만) | K11: L10|L10a|L1|L9|L5|L9a|L1a|L6|L6a | L11: 5/5
A12: V | B12: 핵심구매요소 | C12: 2 | D12: 핵심구매요소 분석 | E12: 필수 | F12: 기능별(또는 고객 여정) 뒤 | G12: S5 | H12: 1절 결과 + 선택 이유 문항 (새 문항 아님) | I12: 전문 텍스트 1페이지. 원본 p31 배너 제목 '핵심구매요소 중요 순위 및 만족도 종합 해석' 불릿 + 하위 불릿만 쓴다. 3장 2절과 달리 우선순위 3단계 그룹은 없다 · 1위 요인의 응답 수와 비율, 그것이 뜻하는 바 · 상위 3개 요인의 누적 비율과 축 해석 · 중위권 · 최하위 요인의 위치 · 주관식에서 반복된 불만과 우선 과제 제안 | J12: 절 드롭 (1절 수치만 출력) | K12: L10a|L24 | L12: 5/5
... A23: X | B23: 종합 결과 및 제언 | C23: 3 | D23: 기능별 고객 제언 종합 | E23: 조건부 | F23: 문서 끝 | G23: S2 | H23: 기능 만족도 + 기능별 이유 문항 | I23: 기능별 부정 카테고리를 뽑을 수 있을 때 | J23: 절 드롭 | K23: L21 | L23: 3/5 (리바랩스 · 케어클 · 이젠오토)
